<?xml version="1.0" ?>
<robot xmlns:xacro="http://ros.org/wiki/xacro">

  <xacro:property name="last_arm_link" value="link_tool0"/>

  <xacro:macro name="motoman_arm" params="name prefix parent *origin reflect">
    <link name="${prefix}link_1_s">
      <visual>
        <origin rpy="0 0 0" xyz="0 0 0"/>
        <geometry>
          <mesh filename="package://motoman_sda10f_support/meshes/sda10f/visual/link_s.stl"/>
        </geometry>
        <material name="blue">
          <color rgba="0.8 0.8 0.8 1"/>
        </material>
      </visual>.
      <collision>
        <origin rpy="0 0 0" xyz="0 0 0"/>
        <geometry>
          <mesh filename="package://motoman_sda10f_support/meshes/sda10f/collision/link_s.stl" />
        </geometry>
      </collision>
      <inertial>
       	<mass value="10.0"/>
        <origin xyz="-0.000265 -0.022912 -0.263484" rpy="0 0 0"/>
        <inertia ixx="0.112042" ixy="-9.49E-06" ixz="5.84E-06" iyy="0.026163" iyz="-0.022776" izz="0.110175"/> 		   
	</inertial>
    </link>
    <link name="${prefix}link_2_l">
      <visual>
        <origin rpy="0 0 0" xyz="0 0 0"/>
        <geometry>
          <mesh filename="package://motoman_sda10f_support/meshes/sda10f/visual/link_l.stl"/>
        </geometry>
        <material name="silver"/>
      </visual>
      <collision>
        <origin rpy="0 0 0" xyz="0 0 0"/>
        <geometry>
          <mesh filename="package://motoman_sda10f_support/meshes/sda10f/collision/link_l.stl"/>
        </geometry>
      </collision>
      <inertial>
       	<mass value="8.0"/>
        <origin xyz="0.0 0.079945 -0.009835" rpy="0 0 0"/>
        <inertia ixx="0.112042" ixy="-9.49E-06" ixz="5.84E-06" iyy="0.026163" iyz="-0.022776" izz="0.110175"/>	
     	</inertial>
    </link>
    <link name="${prefix}link_3_e">
      <visual>
        <origin rpy="0 0 0" xyz="0 0 0"/>
        <geometry>
          <mesh filename="package://motoman_sda10f_support/meshes/sda10f/visual/link_e.stl"/>
        </geometry>
        <material name="blue"/>
      </visual>
      <collision>
        <origin rpy="0 0 0" xyz="0 0 0"/>
        <geometry>
          <mesh filename="package://motoman_sda10f_support/meshes/sda10f/collision/link_e.stl"/>
        </geometry>
      </collision>
      <inertial>
       <mass value="7.5"/>
       <origin xyz="0.0 0.018717 -0.119158" rpy="0 0 0"/>
       <inertia ixx="0.156550" ixy="-8.43E-06" ixz="4.35E-05" iyy="0.152788" iyz="-0.021001" izz="0.017946"/>
      </inertial>
    </link>
    <link name="${prefix}link_4_u">
      <visual>
        <origin rpy="0 0 0" xyz="0 0 0"/>
        <geometry>
          <mesh filename="package://motoman_sda10f_support/meshes/sda10f/visual/link_u.stl"/>
        </geometry>
        <material name="silver"/>
      </visual>
      <collision>
        <origin rpy="0 0 0" xyz="0 0 0"/>
        <geometry>
          <mesh filename="package://motoman_sda10f_support/meshes/sda10f/collision/link_u.stl"/>
        </geometry>
      </collision>
    <inertial>
        <mass value="6.0"/>
        <origin xyz="0.0 0.093003 -0.006433" rpy="0 0 0"/>
        <inertia ixx="0.092098" ixy="-4.04E-05" ixz="-3.81E-06" iyy="0.010300" iyz="0.004406" izz="0.091086"/>
      </inertial>
    </link>
    <link name="${prefix}link_5_r">
      <visual>
        <origin rpy="0 0 0" xyz="0 0 0"/>
        <geometry>
          <mesh filename="package://motoman_sda10f_support/meshes/sda10f/visual/link_r.stl"/>
        </geometry>
        <material name="blue"/>
      </visual>
      <collision>
        <origin rpy="0 0 0" xyz="0 0 0"/>
        <geometry>
          <mesh filename="package://motoman_sda10f_support/meshes/sda10f/collision/link_r.stl"/>
        </geometry>
      </collision>
      <inertial>
        <mass value="5.5"/>
        <origin xyz="0.0 -0.0134 -0.133989" rpy="0 0 0"/>
        <inertia ixx="0.134067" ixy="5.74E-06" ixz="3.19E-05" iyy="0.132025" iyz="0.013502" izz="0.008969"/>
    	</inertial>
    </link>
    <link name="${prefix}link_6_b">
      <visual>
        <origin rpy="0 0 0" xyz="0 0 0"/>
        <geometry>
          <mesh filename="package://motoman_sda10f_support/meshes/sda10f/visual/link_b.stl"/>
        </geometry>
        <material name="silver"/>
      </visual>
      <collision>
        <origin rpy="0 0 0" xyz="0 0 0"/>
        <geometry>
          <mesh filename="package://motoman_sda10f_support/meshes/sda10f/collision/link_b.stl"/>
        </geometry>
      </collision>
	<inertial>
         <mass value="3.5"/>
         <origin xyz="0.0 0.05919 0.001493" rpy="0 0 0"/>
         <inertia ixx="0.024033" ixy="-1.78E-05" ixz="3.03E-06" iyy="0.005402" iyz="-0.002585" izz="0.023675"/>
	</inertial>
    </link>
    <link name="${prefix}link_7_t">
      <visual>
        <geometry>
          <mesh filename="package://motoman_sda10f_support/meshes/sda10f/visual/link_t.stl" />
        </geometry>
        <material name="blue"/>
      </visual>
      <collision>
        <geometry>
          <mesh filename="package://motoman_sda10f_support/meshes/sda10f/collision/link_t.stl" />
        </geometry>
      </collision>
     <inertial>
        <mass value="1.5"/>
        <origin xyz="0.0 0.00015 -0.02467" rpy="0 0 0"/>
        <inertia ixx="0.002083" ixy="0.0" ixz="0.0" iyy="0.002100" iyz="9.8E-07" izz="0.001926"/>
      </inertial>
    </link>
    <link name="${prefix}link_tool0" />



    <!--Color Gazebo-->
    <gazebo reference="${prefix}link_1_s">
		<static>true</static>
    <maxVel>0.0</maxVel>
    <minDepth>0.001</minDepth>
		<material>Gazebo/Blue</material>
	</gazebo>
  <gazebo reference="${prefix}link_2_l">
		<static>true</static>
    <maxVel>0.0</maxVel>
    <minDepth>0.001</minDepth>
	</gazebo>
  <gazebo reference="${prefix}link_3_e">
		<static>true</static>
		<material>Gazebo/Blue</material>
    <maxVel>0.0</maxVel>
   <minDepth>0.001</minDepth>
	</gazebo>
  <gazebo reference="${prefix}link_4_u">
		<static>true</static>
    <maxVel>0.0</maxVel>
    <minDepth>0.001</minDepth>
	</gazebo>
  <gazebo reference="${prefix}link_5_r">
		<static>true</static>
		<material>Gazebo/Blue</material>
    <maxVel>0.0</maxVel>
  <minDepth>0.001</minDepth>
	</gazebo>
  <gazebo reference="${prefix}link_6_b">
		<static>true</static>
    <maxVel>0.0</maxVel>
  <minDepth>0.001</minDepth>
	</gazebo>

<gazebo reference="${prefix}link_7_t">
		<static>true</static>
		<material>Gazebo/Blue</material>
    <maxVel>0.0</maxVel>
  <minDepth>0.001</minDepth>
	</gazebo>

  <!--Joint List-->
    <joint name="${prefix}joint_1_s" type="revolute">
      <parent link="${parent}"/>
      <child link="${prefix}link_1_s"/>
      <origin xyz="0.100 ${reflect*0.265} 0.0" rpy="${radians(90)} 0.0 ${(reflect-1)*radians(90)}"/>
      <axis xyz="0 0 ${-reflect}" />
      <limit lower="${radians(-180)}" upper="${radians(180)}" effort="0" velocity="${radians(170)}" />
      <dynamics damping="0.8"/>
    </joint>
    <joint name="${prefix}joint_2_l" type="revolute">
      <parent link="${prefix}link_1_s"/>
      <child link="${prefix}link_2_l"/>
      <origin xyz="0.0 0.0 0.0" rpy="${radians(-90)} 0.0 0.0"/>
      <axis xyz="0 0 ${-reflect}" />
      <limit lower="${radians(-110)}" upper="${radians(110)}" effort="0" velocity="${radians(170)}" />
      <dynamics damping="0.8"/>
    </joint>
    <joint name="${prefix}joint_3_e" type="revolute">
      <parent link="${prefix}link_2_l"/>
      <child link="${prefix}link_3_e"/>
      <origin xyz="0.0 0.360 0.0" rpy="${radians(90)} 0.0 0.0"/>
      <axis xyz="0 0 ${-reflect}" />
      <limit lower="${radians(-170)}" upper="${radians(170)}" effort="0" velocity="${radians(170)}" />
      <dynamics damping="0.8"/>
    </joint>
    <joint name="${prefix}joint_4_u" type="revolute">
      <parent link="${prefix}link_3_e"/>
      <child link="${prefix}link_4_u"/>
      <origin xyz="0.0 0.0 0.0" rpy="${radians(-90)} 0.0 0.0"/>
      <axis xyz="0 0 ${reflect}" />
      <limit lower="${radians(-135)}" upper="${radians(135)}" effort="0" velocity="${radians(170)}" />
      <dynamics damping="0.8"/>
    </joint>
    <joint name="${prefix}joint_5_r" type="revolute">
      <parent link="${prefix}link_4_u"/>
      <child link="${prefix}link_5_r"/>
      <origin xyz="0.0 0.360 0.0" rpy="${radians(90)} 0.0 0.0"/>
      <axis xyz="0 0 ${reflect}" />
      <limit lower="${radians(-180)}" upper="${radians(180)}" effort="0" velocity="${radians(200)}" />
      <dynamics damping="0.8"/>
    </joint>
    <joint name="${prefix}joint_6_b" type="revolute">
      <parent link="${prefix}link_5_r"/>
      <child link="${prefix}link_6_b"/>
      <origin xyz="0.0 0.0 0.0" rpy="${radians(-90)} 0.0 0.0"/>
      <axis xyz="0 0 ${reflect}" />
      <limit lower="${radians(-110)}" upper="${radians(110)}" effort="0" velocity="${radians(200)}" />
      <dynamics damping="0.8"/>
    </joint>
    <joint name="${prefix}joint_7_t" type="revolute">
      <parent link="${prefix}link_6_b"/>
      <child link="${prefix}link_7_t"/>
      <origin xyz="0.0 0.155 0.0" rpy="${radians(-90)} 0.0 0.0"/>
      <axis xyz="0 0 ${-reflect}" />
      <limit lower="${radians(-180)}" upper="${radians(180)}" effort="0" velocity="${radians(400)}" />
      <dynamics damping="0.8"/>
    </joint>
    <joint name="${prefix}joint_tool0" type="fixed" >
      <parent link="${prefix}link_7_t" />
      <child link="${prefix}link_tool0" />
      <origin xyz="0 0 0" rpy="0 0 ${radians(180)}"/>
      <dynamics damping="0.8"/>
    </joint>
    <!-- end of joint list -->


<!-- transmission list -->
  <transmission name="${prefix}tran_1_s">
    <type>transmission_interface/SimpleTransmission</type>
    <joint name="${prefix}joint_1_s">
      <hardwareInterface>hardware_interface/PositionJointInterface</hardwareInterface>
    </joint>
    <actuator name="${prefix}motor_1_s">
      <mechanicalReduction>1</mechanicalReduction>
    </actuator>
    </transmission>
    
    <transmission name="${prefix}tran_2_l">
    <type>transmission_interface/SimpleTransmission</type>
    <joint name="${prefix}joint_2_l">
      <hardwareInterface>hardware_interface/PositionJointInterface</hardwareInterface>
    </joint>
    <actuator name="${prefix}motor_2_l">
      <mechanicalReduction>1</mechanicalReduction>
    </actuator>
    </transmission>
      
    <transmission name="${prefix}tran_3_e">
    <type>transmission_interface/SimpleTransmission</type>
    <joint name="${prefix}joint_3_e">
      <hardwareInterface>hardware_interface/PositionJointInterface</hardwareInterface>
    </joint>
    <actuator name="${prefix}motor_3_e">
      <mechanicalReduction>1</mechanicalReduction>
    </actuator>
    </transmission>  
      
    <transmission name="${prefix}tran_4_u">
    <type>transmission_interface/SimpleTransmission</type>
    <joint name="${prefix}joint_4_u">
      <hardwareInterface>hardware_interface/PositionJointInterface</hardwareInterface>
    </joint>
    <actuator name="${prefix}motor_4_u">
      <mechanicalReduction>1</mechanicalReduction>
    </actuator>
    </transmission>
      
    <transmission name="${prefix}tran_5_r">
    <type>transmission_interface/SimpleTransmission</type>
    <joint name="${prefix}joint_5_r">
      <hardwareInterface>hardware_interface/PositionJointInterface</hardwareInterface>
    </joint>
    <actuator name="${prefix}motor_5_r">
      <mechanicalReduction>1</mechanicalReduction>
    </actuator>
    </transmission>
    
    <transmission name="${prefix}tran_6_b">
    <type>transmission_interface/SimpleTransmission</type>
    <joint name="${prefix}joint_6_b">
      <hardwareInterface>hardware_interface/PositionJointInterface</hardwareInterface>
    </joint>
    <actuator name="${prefix}motor_6_b">
      <mechanicalReduction>1</mechanicalReduction>
    </actuator>
    </transmission>
      
    <transmission name="${prefix}tran_7_t">
    <type>transmission_interface/SimpleTransmission</type>
    <joint name="${prefix}joint_7_t">
      <hardwareInterface>hardware_interface/PositionJointInterface</hardwareInterface>
    </joint>
    <actuator name="${prefix}motor_7_t">
      <mechanicalReduction>1</mechanicalReduction>
    </actuator>
    </transmission>  	
		<!-- end of transmission list -->		

  </xacro:macro>
</robot>